<!-- ======================================================
	
	Model 		: Nextage Open Right Arm for grasping
	Author		: Beltran Cristian
	Institute   : System Innovation, Osaka University.
	Contacts 	: cristian_beltran@ieee.org	
	Last edits 	: 21.02.2018

====================================================== -->
<mujoco model="nextage_hands">
    <compiler inertiafromgeom="true"
              angle="radian"
              coordinate="local"
              meshdir="meshes/"/>

    <option timestep=".02"
            gravity="0 0 -.01"
            iterations="500"
            solver="CG">
    </option>

    <default>
        <joint armature="1" frictionloss="20" damping="0" limited="true" />
        <geom  friction=".5 .1 .1"  condim="3" contype="0" conaffinity="0" />

        <default class="nxo">
            <joint armature="0.01" damping="5" frictionloss=".5" limited="true" />
            <geom material="MatPlastic" />
        </default>                
   </default>   
    
    <asset>
        <texture builtin="gradient" height="10" rgb1=".4 .5 .6" rgb2="0 0 0" type="skybox" width="10"/>
        <texture builtin="flat" height="10" mark="cross" markrgb="1 1 1" name="texgeom" random="0.01" rgb1="0.8 0.6 0.4" rgb2="0.8 0.6 0.4" type="cube" width="10"/>
        <texture builtin="checker" height="10" name="texplane" rgb1="0 0 0" rgb2="0.8 0.8 0.8" type="2d" width="10"/>

        <material name="MatPlane" reflectance="0.5" shininess="1" specular="1" texrepeat="60 60" texture="texplane"/>
        <material name="MatPlastic" specular=".8" shininess=".6" reflectance="0.5" rgba=".4 .41 .4 1"/>
        <material name="geom" texture="texgeom" texuniform="true"/>
 
        <mesh name="WAIST_Link_mesh" file="WAIST_Link_mesh.stl" />
        <mesh name="CHEST_JOINT0_Link_mesh" file="CHEST_JOINT0_Link_mesh.stl" />
        <mesh name="HEAD_JOINT0_Link_mesh" file="HEAD_JOINT0_Link_mesh.stl" />
        <mesh name="HEAD_JOINT1_Link_mesh" file="HEAD_JOINT1_Link_mesh.stl" />
        <mesh name="LARM_JOINT0_Link_mesh" file="LARM_JOINT0_Link_mesh.stl" />
        <mesh name="LARM_JOINT1_Link_mesh" file="LARM_JOINT1_Link_mesh.stl" />
        <mesh name="LARM_JOINT2_Link_mesh" file="LARM_JOINT2_Link_mesh.stl" />
        <mesh name="LARM_JOINT3_Link_mesh" file="LARM_JOINT3_Link_mesh.stl" />
        <mesh name="LARM_JOINT4_Link_mesh" file="LARM_JOINT4_Link_mesh.stl" />
        <mesh name="LARM_JOINT5_Link_mesh" file="LARM_JOINT5_Link_mesh.stl" />
        <mesh name="LHAND_L_Link_mesh" file="LHAND_L_Link_mesh.stl" />
        <mesh name="LHAND_R_Link_mesh" file="LHAND_R_Link_mesh.stl" />
        <mesh name="RARM_JOINT0_Link_mesh" file="RARM_JOINT0_Link_mesh.stl" />
        <mesh name="RARM_JOINT1_Link_mesh" file="RARM_JOINT1_Link_mesh.stl" />
        <mesh name="RARM_JOINT2_Link_mesh" file="RARM_JOINT2_Link_mesh.stl" />
        <mesh name="RARM_JOINT3_Link_mesh" file="RARM_JOINT3_Link_mesh.stl" />
        <mesh name="RARM_JOINT4_Link_mesh" file="RARM_JOINT4_Link_mesh.stl" />
        <mesh name="RARM_JOINT5_Link_mesh" file="RARM_JOINT5_Link_mesh.stl" />
        <mesh name="RHAND_L_Link_mesh" file="RHAND_L_Link_mesh.stl" />
        <mesh name="RHAND_R_Link_mesh" file="RHAND_R_Link_mesh.stl" />
        <mesh name="TABLE_mesh" file="table.stl" scale="1 1 1.14"/>
        <mesh name="CAN_mesh" file="can.stl" />
        <mesh name="CUBE_mesh" file="cube.stl" scale="2 2 2"/>
        <mesh name="L_mesh" file="L.stl" scale="2 2 2"/>
    </asset>
    <worldbody>
        <light cutoff="100" diffuse="1 1 1" dir="-0 0 -1.3" directional="true" exponent="1" pos="0 0 1.3" specular=".1 .1 .1"/>
        
        <!-- Floor -->
        <geom material="MatPlane" name="floor" pos="0 0 -0.97" rgba="0.8 0.9 0.8 1" size="10 10 0.125" type="plane"  contype="1" conaffinity="1" />
        
        <!-- Static Objects -->
        <body name="table" pos="0 0 0">
            <geom pos="0.5 0 -0.855" name="table" type="mesh" mesh="TABLE_mesh" rgba="0.5 0.5 0.5 1" contype="1" conaffinity="1" />
        </body>
        
        <!-- Robot -->
        <body name="WAIST_Link" pos="0 0 0" childclass="nxo">
            <geom pos="0 0 0.97" type="mesh" mesh="WAIST_Link_mesh" rgba=".3 .3 .3 1" />
            <body name="CHEST_JOINT0_Link" pos="0 0 0">
                <inertial pos="-0.00493378 -0.00097682 0.344052" quat="0.708324 0.705867 -0.00529093 0.00038141" mass="6.20761" diaginertia="0.06396 0.05011 0.0310827" />
                <joint name="CHEST_JOINT0" pos="0 0 0" axis="0 0 1" range="-2.84489 2.84489" />
                <geom type="mesh" mesh="CHEST_JOINT0_Link_mesh" rgba="1 1 1 1"/>
                <body name="HEAD_JOINT0_Link" pos="0 0 0.5695">
                    <inertial pos="-2.292e-05 0.00547848 -0.00784016" quat="0.658128 0.752902 0.00186175 -0.00169192" mass="0.317929" diaginertia="0.000276822 0.000211012 0.000128616" />
                    <geom pos="0 0 0.5695" type="mesh" mesh="HEAD_JOINT0_Link_mesh" rgba=".1 .1 .1 1" />
                    <body name="HEAD_JOINT1_Link" pos="0 0 0">
                        <inertial pos="5.02e-06 -0.0166777 0.0163153" quat="0.590382 0.807124 -0.000511861 4.94785e-05" mass="0.0808593" diaginertia="8.07e-05 7.04287e-05 2.61913e-05" />
                        <geom type="mesh" mesh="HEAD_JOINT1_Link_mesh" rgba=".9 .9 .9 1"/>
                    </body>
                </body>
                <body name="LARM_JOINT0_Link" pos="0 0.145 0.370296" quat="0.991445 -0.130526 0 0">
                    <inertial pos="-0.00226388 -0.00521383 0.0156081" quat="0.801199 -0.06689 -0.0387916 0.593381" mass="1.32626" diaginertia="0.00243831 0.00205563 0.0014035" />
                    <geom pos="0 0.145 0.370296" quat="0.991445 -0.130526 0 0" type="mesh" mesh="LARM_JOINT0_Link_mesh" rgba=".2 .2 .2 1"/>
                    <body name="LARM_JOINT1_Link" pos="0 0 0">
                        <inertial pos="-5.236e-05 0.0583134 -0.107061" quat="0.997039 0.0768717 -0.000264302 0.00199585" mass="1.14898" diaginertia="0.0154168 0.0150432 0.000934273" />
                        <geom type="mesh" mesh="LARM_JOINT1_Link_mesh" rgba=".2 .2 .2 1"/>
                        <body name="LARM_JOINT2_Link" pos="0 0.095 -0.25">
                            <inertial pos="-2.254e-05 0.00167107 -0.0715116" quat="0.999463 -0.0309491 -0.000806169 -0.01076" mass="0.577518" diaginertia="0.00143967 0.00142233 0.000192489" />
                            <geom pos="0 0.095 -0.25" type="mesh" mesh="LARM_JOINT2_Link_mesh" rgba=".2 .2 .2 1"/>
                            <body name="LARM_JOINT3_Link" pos="-0.03 0 0">
                                <inertial pos="-1.788e-05 -0.00395812 -0.20273" quat="0.999848 -0.0172581 -0.000422822 0.00255873" mass="0.457418" diaginertia="0.000692051 0.000689691 0.000134428" />
                                <geom pos="-0.03 0 0" type="mesh" mesh="LARM_JOINT3_Link_mesh" rgba=".2 .2 .2 1"/>
                                <body name="LARM_JOINT4_Link" pos="0 0 -0.235">
                                    <inertial pos="0.00243131 0.00379733 -0.0577036" quat="0.99659 -0.0718122 -0.00754115 0.0399433" mass="0.418434" diaginertia="0.00052037 0.00051339 0.000132129" />
                                    <geom pos="0 0 -0.235" type="mesh" mesh="LARM_JOINT4_Link_mesh" rgba=".2 .2 .2 1"/>
                                    <body name="LARM_JOINT5_Link" pos="-0.099 0 -0.09">
                                        <inertial pos="-0.048476 -3.2e-06 -0.0388988" quat="0.702339 0.0868218 0.0869122 0.701162" mass="1.05156" diaginertia="0.00209392 0.00204753 0.00025107" />
                                        <geom pos="-0.065 0 -0.09" type="mesh" mesh="LARM_JOINT5_Link_mesh" rgba=".8 .8 .8 1"/>
                                        <body name="LHAND_L_Link" pos="-0.062 0 0">
                                            <inertial pos="0 0 0" mass="0.01" diaginertia="0.0001 0.0001 0.0001" />
                                            <geom pos="-0.028 0 0" type="mesh" mesh="LHAND_L_Link_mesh" rgba=".12 .05 .2 1"/>
                                        </body>
                                        <body name="LHAND_R_Link" pos="-0.062 0 0">
                                            <inertial pos="0 0 0" mass="0.01" diaginertia="0.0001 0.0001 0.0001" />
                                            <geom pos="-0.028 0 0" type="mesh" mesh="LHAND_R_Link_mesh" rgba=".12 .05 .2 1"/>
                                        </body>
                                    </body>
                                </body>
                            </body>
                        </body>
                    </body>
                </body>
                <body name="RARM_JOINT0_Link" pos="0 -0.145 0.370296" quat="0.991445 0.130526 0 0">
                    <inertial pos="-0.00226388 0.00521383 0.0156081" quat="0.593381 -0.0387916 -0.06689 0.801199" mass="1.32626" diaginertia="0.00243831 0.00205563 0.0014035" />
                    <joint name="RARM_JOINT0" pos="0 0 0" axis="0 0 1" range="-1.53589 1.53589" />
                    <geom pos="0 -0.145 0.370296" quat="0.991445 0.130526 0 0" type="mesh" mesh="RARM_JOINT0_Link_mesh" rgba=".2 .2 .2 1" />
                    <body name="RARM_JOINT1_Link" pos="0 0 0" >
                        <inertial pos="-5.236e-05 -0.0583134 -0.107061" quat="0.997039 -0.0768717 -0.000264302 -0.00199585" mass="1.14898" diaginertia="0.0154168 0.0150432 0.000934273" />
                        <joint name="RARM_JOINT1" pos="0 0 0" axis="0 1 0" range="-2.44346 1.0472" />
                        <geom type="mesh" mesh="RARM_JOINT1_Link_mesh" rgba=".2 .2 .2 1" />
                        <body name="RARM_JOINT2_Link" pos="0 -0.095 -0.25">
                            <inertial pos="-2.254e-05 -0.00167107 -0.0715116" quat="0.999463 0.0309491 -0.000806169 0.01076" mass="0.577518" diaginertia="0.00143967 0.00142233 0.000192489" />
                            <joint name="RARM_JOINT2" pos="0 0 0" axis="0 1 0" range="-2.75762 0" />
                            <geom pos="0 -0.095 -0.25" type="mesh" mesh="RARM_JOINT2_Link_mesh" rgba=".2 .2 .2 1" />
                            <body name="RARM_JOINT3_Link" pos="-0.03 0 0">
                                <inertial pos="-1.788e-05 0.00395812 -0.20273" quat="0.999848 0.0172581 -0.000422822 -0.00255873" mass="0.457418" diaginertia="0.000692051 0.000689691 0.000134428" />
                                <joint name="RARM_JOINT3" pos="0 0 0" axis="0 0 1" range="-2.87979 1.8326" />
                                <geom pos="-0.03 0 0" type="mesh" mesh="RARM_JOINT3_Link_mesh" rgba=".2 .2 .2 1" />
                                <body name="RARM_JOINT4_Link" pos="0 0 -0.235">
                                    <inertial pos="0.00243131 -0.00379733 -0.0577036" quat="0.99659 0.0718122 -0.00754115 -0.0399433" mass="0.418434" diaginertia="0.00052037 0.00051339 0.000132129" />
                                    <joint name="RARM_JOINT4" pos="0 0 0" axis="0 1 0" range="-1.74533 1.74533" />
                                    <geom pos="0 0 -0.235" type="mesh" mesh="RARM_JOINT4_Link_mesh" rgba=".2 .2 .2 1" />
                                    <body name="RARM_JOINT5_Link" pos="-0.099 0 -0.09">
                                        <inertial pos="-0.048476 3.2e-06 -0.0388988" quat="0.701162 0.0869122 0.0868218 0.702339" mass="1.05156" diaginertia="0.00209392 0.00204753 0.00025107" />
                                        <joint name="RARM_JOINT5" pos="0 0 0" axis="1 0 0" range="-2.84489 2.84489" />
                                        <geom pos="-0.065 0 -0.09" type="mesh" mesh="RARM_JOINT5_Link_mesh" rgba=".8 .8 .8 1" contype="1" conaffinity="1"/>

                                        <site name="eefp1" pos="0.0 0.0 0.0" size="0.001" rgba=".12 1 .2 1" />
                                        <site name="eefp2" pos="-0.12 0.0 0.0" size="0.001" rgba=".12 1 .2 1" />
                                        <site name="eefp3" pos="0.0 0 -0.08" size="0.001" rgba=".12 1 .2 1" />
                                        
                                        <body name="RHAND_L_Link" pos="-0.062 0 0">
                                            <inertial pos="0 0 0" mass="0.01" diaginertia="0.0001 0.0001 0.0001" />
                                            <joint name="RHAND_L" pos="0 0 0" axis="0 1 0" type="slide" range="0 0.03" />
                                            <geom pos="-0.028 0 0" type="mesh" mesh="RHAND_L_Link_mesh" rgba=".12 .05 .4 1" contype="1" conaffinity="1"/>
                                        </body>
                                        <body name="RHAND_R_Link" pos="-0.062 0 0">
                                            <inertial pos="0 0 0" mass="0.01" diaginertia="0.0001 0.0001 0.0001" />
                                            <joint name="RHAND_R" pos="0 0 0" axis="0 1 0" type="slide" range="-0.03 0" />
                                            <geom pos="-0.028 0 0" type="mesh" mesh="RHAND_R_Link_mesh" rgba=".12 .05 .4 1" contype="1" conaffinity="1"/>
                                        </body>
                                    </body>
                                </body>
                            </body>
                        </body>
                    </body>
                </body>
            </body>
        </body>

        <!-- Objects -->
        <!-- <body name="can" pos="0 0 0">
            <geom pos="0.45 0 0.01" name="can" type="mesh" mesh="CAN_mesh" rgba="1 0.5 0.5 1"   contype="1" conaffinity="1"  />
            <joint armature="0" axis="1 0 0" damping="0" limited="false" name="can_x" pos="0 0 0" stiffness="0" type="slide"/>
            <joint armature="0" axis="0 1 0" damping="0" limited="false" name="can_y" pos="0 0 0" stiffness="0" type="slide"/>
            <joint armature="0" axis="0 0 1" damping="0" limited="false" name="can_z" pos="0 0 0" stiffness="0" type="slide"/>
        </body>

        <body name="cube" pos="0 0 0">
            <geom pos="0.45 0.1 0.0" name="cube" type="mesh" mesh="CUBE_mesh" rgba="0.4 .8 0.4 1"  contype="1" conaffinity="1" />
            <joint armature="0" axis="1 0 0" damping="0" limited="false" name="cube_x" pos="0 0 0" stiffness="0" type="slide"/>
            <joint armature="0" axis="0 1 0" damping="0" limited="false" name="cube_y" pos="0 0 0" stiffness="0" type="slide"/>
            <joint armature="0" axis="0 0 1" damping="0" limited="false" name="cube_z" pos="0 0 0" stiffness="0" type="slide"/>
        </body> -->

        <body name="l" pos="0 0 0">
            <geom pos="0.45 0.1 -0.02" name="l" type="mesh" mesh="L_mesh" rgba="0.4 .4 0.8 1"  contype="1" conaffinity="1" />
            <joint axis="1 0 0" limited="false" name="l_x" pos="0 0 0" type="slide"/>
            <joint axis="0 1 0" limited="false" name="l_y" pos="0 0 0" type="slide"/>
            <joint axis="0 0 1" limited="false" name="l_z" pos="0 0 0" type="slide"/>
        </body>
    </worldbody>

    <actuator>
        <position name='CHEST_JOINT0' 	joint='CHEST_JOINT0' ctrlrange='-2.84489 2.84489'  	/>
		<position name='RARM_JOINT0'  	joint='RARM_JOINT0'  ctrlrange='-1.53589 1.53589'  	/>
		<position name='RARM_JOINT1'    joint='RARM_JOINT1'  ctrlrange='-2.44346 1.0472'	/>
		<position name='RARM_JOINT2'    joint='RARM_JOINT2'  ctrlrange='-2.75762 0'      	/>
		<position name='RARM_JOINT3'    joint='RARM_JOINT3'  ctrlrange='-2.87979 1.8326'   	/>
		<position name='RARM_JOINT4'    joint='RARM_JOINT4'  ctrlrange='-1.74533 1.74533'  	/>
		<position name='RARM_JOINT5'    joint='RARM_JOINT5'  ctrlrange='-2.84489 2.84489' 	/>
		<position name='RHAND_L'        joint='RHAND_L'      ctrlrange=' 0       0.03'   	/>
		<position name='RHAND_R'        joint='RHAND_R'      ctrlrange='-0.03    0' 	    />
    </actuator>

</mujoco>

